Workbook

Sheet AI Events_MD&A
A1: Wolters Kluwer — AI Evidence, MD&A & Commercialization Timeline
A2: A. AI & Digital Commercialization Timeline
A3: Date / Year | B3: Phase | C3: Scope | D3: Official Evidence / Management Commentary | E3: Quantified Evidence | F3: Financial Mechanism | G3: Model Use | H3: Document / Release
A4: 2021 | B4: Historical AI / cloud foundation | C4: Group / T&A | D4: AI, NLP, RPA and predictive analytics were already deployed; CCH Axcess cloud adoption supported professional workflows. 2021–23 is pre-GenAI acceleration, not pre-AI. | E4: Product development = 10% of revenue | F4: Cloud migration + workflow embedment + recurring revenue durability | G4: Historical baseline / attribution guardrail | H4: 2021 Annual Report
A5: 2022 | B5: Expert solutions / cloud scale | C5: Group | D5: Recurring digital/cloud expert solutions supported 6% organic growth while management raised product development to a record level. | E5: 11% of revenue invested in product development; expert solutions = 56% of revenue | F5: Recurring/cloud mix + product investment | G5: Baseline before accelerated GenAI commercialization | H5: 2022 Annual Report
A6: 2023 | B6: GenAI experimentation | C6: Group / T&A | D6: Management shifted attention and funding toward generative-AI opportunities; first GenAI-enabled products were released. AI had already been used for more than a decade. | E6: ≈€615m product development; ≈50% of digital revenue from products with AI embedded; T&A cloud +17% | F6: Product innovation + cloud adoption + future AI monetization | G6: Marks GenAI ramp-up; no direct AI revenue attribution | H6: 2023 Annual Report
A7: 2023-10-20 | B7: GenAI showcase | C7: T&A direct | D7: Five GenAI use cases demonstrated across search, firm guidance, client relationships, scorecards and benchmarking. | E7: 5 showcased GenAI use cases | F7: Customer productivity + client service + profitability insights | G7: Evidence of experimentation before commercial launch | H7: CCH Connections GenAI Showcase
A8: 2024 | B8: Commercial GenAI | C8: Group / T&A | D8: GenAI search, summarization, Q&A and virtual assistants rolled out. T&A cloud growth was driven by CCH Axcess migration and additional workflow modules. | E8: ≈€660m product development; T&A cloud +19% organic; N.A. cloud +20%; >50% digital revenue from AI-leveraging products | F8: Subscription/cloud growth + workflow upsell + operating leverage | G8: Core 2024 commercialization rationale | H8: 2024 Annual Report / FY Results
A9: 2024-05-06 | B9: Commercial GenAI launch | C9: T&A direct | D9: GenAI Q&A launched inside CCH AnswerConnect, embedding natural-language assistance into the tax research workflow. | E9: Commercial GenAI launch | F9: Research time savings + premium product value | G9: Commercialization breakpoint | H9: CCH AnswerConnect GenAI
A10: 2025 | B10: Expert AI / agentic commercialization | C10: Group / T&A | D10: Management identified AI growth channels through retention, upsell, new products and adjacent segments. Expert AI was embedded into multiple high-value workflows. | E10: ≈€650m product development; nearly 70% digital revenue AI-powered; 83% recurring; >90% renewal rates for most core solutions | F10: Retention + upsell + new products + adjacency + recurring-revenue durability | G10: Defines monetization channels used in ROI | H10: 2025 Annual Report
A11: 2025-10-15 | B11: Agentic platform launch | C11: T&A direct | D11: CCH Axcess Expert AI launched as an agentic-ready platform across tax, audit and firm management; FY commentary cited significant productivity benefits. | E11: CCH Axcess native cloud +19% organic in FY2025 | F11: AI module upsell + workflow automation + cloud retention | G11: Primary AI ROI initiative launch point | H11: CCH Axcess Expert AI launch
A12: 2026-Q1 | B12: Early agentic adoption | C12: T&A direct | D12: Recurring T&A revenue sustained 7% organic growth, driven by cloud solutions. Early commercial adoption of new CCH Axcess agentic modules was reported. | E12: >150 firms using Intelligence / Client Collaboration | F12: Adoption + cloud recurring revenue | G12: Early adoption bridge into 2026E | H12: Q1 2026 Trading Update
A13: 2026-05-13 | B13: Agentic expansion | C13: T&A direct | D13: CCH Axcess Advisor became generally available, using client/compliance data to identify and scale advisory opportunities. | E13: Commercial product launch | F13: New product + advisory upsell + customer revenue opportunity | G13: Supports commercial-expansion value channel | H13: CCH Axcess Advisor launch
A14: 2026-06 | B14: Enterprise AI collaboration | C14: T&A direct / Group | D14: Wolters Kluwer and OpenAI expanded enterprise collaboration; OpenAI models power CCH Axcess Expert AI agentic workflows. | E14: Company-reported 20–30% reduction in manual tasks from CCH Axcess agentic solutions | F14: Customer productivity + AI delivery architecture | G14: Operating-benefit evidence; not WK contract pricing | H14: Wolters Kluwer + OpenAI collaboration
A15: 2026-06-29 | B15: Workflow automation scale | C15: T&A direct | D15: AI-powered Scan and complex K-1 ingestion expanded low-touch tax preparation and document automation. | E15: Early users: 30–70% efficiency gains; K-1 manual effort down 60–80% | F15: Customer productivity + capacity + retention | G15: Supporting workflow-specific evidence only | H15: Expert AI Scan / K-1 expansion
A16: 2026-H1 | B16: Commercial adoption / scaling | C16: T&A direct | D16: T&A recurring growth remained strong and North American cloud growth sustained double digits as firms migrated and added workflow modules. | E16: T&A revenue €847m; organic +6%; margin 36.3%; recurring 93%; N.A. cloud +18%; ≈250 AI-module firms | F16: Observed adoption + recurring/cloud growth + operating leverage | G16: Anchors 2026 adoption and before/after analysis | H16: 2026 Half-Year Results
A17: 2026 onward | B17: AI investment scale-up | C17: Group | D17: Management plans to raise annual product-development spending to 12–13% of revenue to advance the AI strategy while still targeting margin expansion. | E17: 12–13% product development; 2026 adjusted operating margin ≈28% | F17: Higher near-term investment for future recurring growth / monetization | G17: Key forecast cost/investment anchor | H17: 2025 Annual Report / 2026 H1 Results
A19: B. AI Capital Allocation, Market Demand & Cross-Division Commercialization Evidence
A20: Date / Year | B20: Phase | C20: Scope | D20: Official Evidence / Management Commentary | E20: Quantified Evidence | F20: Financial Mechanism | G20: Model Use | H20: Document / Release
A21: 2021 | B21: AI / analytics acquisition precedent | C21: Former CCH Tagetik / CP&ESG | D21: Vanguard Software acquired to extend planning and predictive analytics capabilities. | E21: ≈$110m cash; 2020 revenue ≈$7.2m; ≈55% subscription-cloud mix; recurring cloud +33%; ROIC >8% WACC within 3–5 years | F21: AI/analytics M&A discipline + hurdle-rate precedent | G21: WACC / capital-allocation precedent | H21: Vanguard Software acquisition
A22: 2022 | B22: AI acquisition precedent | C22: Legal & Regulatory | D22: Della AI, an NLP/contract-analysis specialist, acquired to strengthen legal AI capabilities. | E22: ROIC expected above 8% WACC within 3–5 years | F22: Repeated company hurdle for AI-related investment | G22: WACC / capital-allocation precedent | H22: Della AI acquisition
A23: 2025 | B23: AI M&A commercialization precedent | C23: Legal & Regulatory | D23: Wolters Kluwer agreed to acquire Libra Technology, a legal AI assistant provider. | E23: Up to €90m consideration; €30m upfront; ≈€5m ARR expected; ROIC at/above 8% after-tax WACC within 3–5 years | F23: Concrete AI transaction economics + investment hurdle | G23: Supports 8% WACC anchor and 3–5 year return discipline | H23: Libra Technology acquisition
A24: 2025 | B24: Market demand evidence | C24: Accounting industry | D24: Future Ready Accountant reported rapid movement from experimentation to regular AI use across accounting firms. | E24: AI adoption 9%→41%; 77% plan more AI investment; 35% daily use; 73% of regular users report better-than-expected outcomes | F24: Rising addressable demand for AI workflow modules | G24: Adoption rationale only — not CCH Axcess adoption | H24: 2025 Future Ready Accountant
A25: 2026-01 | B25: Post-acquisition commercialization | C25: Legal & Regulatory | D25: Libra technology integrated with Wolters Kluwer content and launched as the Libra Legal AI Workspace in the Netherlands. | E25: Acquisition-to-launch sequence | F25: Build/buy/integrate/monetize precedent | G25: Cross-division commercialization precedent | H25: Libra Legal AI Workspace launch
A26: 2026 | B26: Workflow productivity evidence | C26: Legal & Regulatory | D26: Passport introduced AI-powered matter-summary capabilities across legal matter documents, invoices and tasks. | E26: Clients reduced time spent on strategic matter reviews by 75% | F26: Cross-division proof that embedded Expert AI can create measurable workflow savings | G26: Supporting benchmark only | H26: Passport AI matter summaries
A27: 2026 | B27: Enterprise AI adoption | C27: Legal & Regulatory | D27: CRIDO selected Libra after a pilot and benchmark against alternative AI tools. | E27: Nearly 200 lawyers/advisors adopting the AI workspace | F27: Customer validation / commercial adoption precedent | G27: Supporting adoption precedent only | H27: CRIDO chooses Libra
A28: 2026 | B28: Finance workflow / AI evidence | C28: Corporate Performance & ESG | D28: CCH Tagetik evidence highlights demand for unified cloud finance platforms with AI-enabled forecasting, automation and reporting. | E28: Customer example accelerated financial close by ≈5 working days | F28: Finance-AI workflow value / integration evidence | G28: Context for AI-in-finance thesis, not T&A revenue | H28: 2026 CCH Tagetik analyst recognitions
A30: C. Management Commentary Linking Financial Performance to Operating Drivers
A31: Year | B31: Financial Area | C31: Reported Result / Direction | D31: AI / Digital Relevance | E31: Attribution Treatment | F31: Forecast Driver | G31: Grade | H31: Page / Section
A32: 2021 | B32: Group / T&A | C32: Group revenue €4,771m; margin 25.3%; T&A PF organic +5%; T&A margin 30.8% | D32: Cloud workflow foundation before GenAI acceleration | E32: Do not attribute 2021 results to GenAI | F32: Recurring/cloud migration; normalized cost base | G32: A+ | H32: Group review / T&A section
A33: 2022 | B33: Group / T&A | C33: Group organic +6%; margin 26.1%; T&A PF organic +8%; margin 32.6% | D33: Digital/cloud scale and product investment are the economic baseline | E33: Baseline only | F33: Recurring/cloud growth + operating leverage + innovation spend | G33: A+ | H33: Group/T&A review
A34: 2023 | B34: T&A | C34: Revenue €1,466m; organic +8%; margin 32.7% | D34: GenAI experimentation started to scale late in the year | E34: Correlation only; no AI revenue attribution | F34: Recurring software + cloud + product/personnel investment | G34: A+ | H34: T&A section
A35: 2024 | B35: T&A | C35: Revenue €1,561m; organic +7%; margin 33.2% | D35: Commercial GenAI features introduced alongside cloud/module expansion | E35: Association only; direct AI revenue not disclosed | F35: Cloud/module adoption + operating leverage; GenAI supports future upsell | G35: A+ | H35: T&A p.23 / FY Results p.9
A36: 2025 | B36: T&A | C36: Revenue €1,660m; organic +7%; margin 35.2%; CCH Axcess native cloud +19% | D36: Expert AI becomes a commercial module layer; management identifies retention, upsell, new products and adjacencies | E36: Do not attribute all 2025 CCH Axcess growth to AI | F36: Cloud/module penetration + AI attach rate + operating leverage | G36: A+ | H36: T&A p.25 / FY Results p.9
A37: 2026 H1 | B37: T&A / Group | C37: Group organic +5%; T&A organic +6%; T&A margin 36.3%; ≈250 AI firms | D37: First observed commercial adoption anchor for agentic AI | E37: Use adoption point, not company growth, for AI ROI attribution | F37: 7% FY T&A growth guidance; higher AI investment; continuing cloud adoption | G37: A+ | H37: T&A p.10 / outlook p.2

Sheet Historical Data
A2: Financial Statement Model for Wolters Kluwer
A3: € mm except per share
A5: Company name | B5: Wolters Kluwer N.V.
A6: Ticker | B6: WKL / WKL.AS
A7: Historical baseline | B7: 2021A–2023A
A8: GenAI commercialization | B8: 2024A
A9: Agentic AI launch | B9: 2025A
A10: Diluted weighted-average shares (m) | B10: 231.8
A11: Project objective | B11: Quantify financial value from AI and return from continued agentic-AI scaling
A13: INCOME STATEMENT
B14: 2021A | C14: 2022A | D14: 2023A | E14: 2024A | F14: 2025A
A16: Revenue | B16: 4771 | C16: 5453 | D16: 5584 | E16: 5916 | F16: 6125
A17: Cost of revenue (enter as -) | B17: -1374 | C17: -1578 | D17: -1576 | E17: -1626 | F17: -1625
A18: Gross Profit | B18: =SUM(B16:B17) -> 3397 | C18: =SUM(C16:C17) -> 3875 | D18: =SUM(D16:D17) -> 4008 | E18: =SUM(E16:E17) -> 4290 | F18: =SUM(F16:F17) -> 4500
A19: Product development / R&D & editorial (enter as -) | B19: -466 | C19: -541 | D19: -591 | E19: -688 | F19: -724
A20: Sales & Marketing (enter as -) | B20: -806 | C20: -914 | D20: -929 | E20: -969 | F20: -975
A21: General & Administrative (enter as -) | B21: -920 | C21: -996 | D21: -1012 | E21: -1033 | F21: -1114
A22: Amortization of acquired intangibles (enter as -) | B22: -164 | C22: -160 | D22: -146 | E22: -149 | F22: -157
A23: Other operating income / (expense), net | B23: -29 | C23: 69 | D23: -7 | E23: -10 | F23: 205
A24: Operating profit (EBIT) | B24: =SUM(B18:B23) -> 1012 | C24: =SUM(C18:C23) -> 1333 | D24: =SUM(D18:D23) -> 1323 | E24: =SUM(E18:E23) -> 1441 | F24: =SUM(F18:F23) -> 1735
A25: Financing income | B25: 4 | C25: 21 | D25: 55 | E25: 52 | F25: 29
A26: Financing expense (enter as -) | B26: -82 | C26: -77 | D26: -82 | E26: -114 | F26: -115
A27: Other finance income / (expense), net | B27: -6 | C27: -1 | D27: 0 | E27: -3 | F27: -2
A28: Pretax profit | B28: =SUM(B24:B27) -> 928 | C28: =SUM(C24:C27) -> 1276 | D28: =SUM(D24:D27) -> 1296 | E28: =SUM(E24:E27) -> 1376 | F28: =SUM(F24:F27) -> 1647
A29: Taxes (enter expense as -) | B29: -201 | C29: -249 | D29: -290 | E29: -299 | F29: -341
A30: Net income | B30: =SUM(B28:B29) -> 727 | C30: =SUM(C28:C29) -> 1027 | D30: =SUM(D28:D29) -> 1006 | E30: =SUM(E28:E29) -> 1077 | F30: =SUM(F28:F29) -> 1306
A32: Depreciation & amortization | B32: 473 | C32: 466 | D32: 445 | E32: 479 | F32: 477
A33: EBITDA | B33: =B24+B32 -> 1485 | C33: =C24+C32 -> 1799 | D33: =D24+D32 -> 1768 | E33: =E24+E32 -> 1920 | F33: =F24+F32 -> 2212
A34: Adjusted operating profit | B34: 1205 | C34: 1424 | D34: 1476 | E34: 1600 | F34: 1687
A35: Adjusted EBITDA | B35: 1514 | C35: 1730 | D35: 1775 | E35: 1930 | F35: 2007
A38: Growth rates & margins
A39: Revenue growth | C39: =C16/B16-1 -> 0.14294697 | D39: =D16/C16-1 -> 0.024023473 | E39: =E16/D16-1 -> 0.059455587 | F39: =F16/E16-1 -> 0.035327924
A40: Gross profit margin | B40: =B18/B16 -> 0.71201006 | C40: =C18/C16 -> 0.71061801 | D40: =D18/D16 -> 0.71776504 | E40: =E18/E16 -> 0.72515213 | F40: =F18/F16 -> 0.73469388
A41: Product development / R&D % of revenue | B41: =-B19/B16 -> 0.097673444 | C41: =-C19/C16 -> 0.099211443 | D41: =-D19/D16 -> 0.10583811 | E41: =-E19/E16 -> 0.11629479 | F41: =-F19/F16 -> 0.11820408
A42: S&M % of revenue | B42: =-B20/B16 -> 0.16893733 | C42: =-C20/C16 -> 0.16761416 | D42: =-D20/D16 -> 0.16636819 | E42: =-E20/E16 -> 0.1637931 | F42: =-F20/F16 -> 0.15918367
A43: G&A % of revenue | B43: =-SUM(B21:B22)/B16 -> 0.22720604 | C43: =-SUM(C21:C22)/C16 -> 0.2119934 | D43: =-SUM(D21:D22)/D16 -> 0.20737822 | E43: =-SUM(E21:E22)/E16 -> 0.19979716 | F43: =-SUM(F21:F22)/F16 -> 0.2075102
A44: Operating margin | B44: =B24/B16 -> 0.21211486 | C44: =C24/C16 -> 0.24445259 | D44: =D24/D16 -> 0.23692693 | E44: =E24/E16 -> 0.24357674 | F44: =F24/F16 -> 0.28326531
A45: Effective tax rate | B45: =-B29/B28 -> 0.21659483 | C45: =-C29/C28 -> 0.19514107 | D45: =-D29/D28 -> 0.22376543 | E45: =-E29/E28 -> 0.21729651 | F45: =-F29/F28 -> 0.20704311
A46: Adjusted operating margin | B46: =B34/B16 -> 0.2525676 | C46: =C34/C16 -> 0.26114066 | D46: =D34/D16 -> 0.26432665 | E46: =E34/E16 -> 0.27045301 | F46: =F34/F16 -> 0.27542857
A47: Total product development % of revenue | B47: 0.1 | C47: 0.11 | D47: 0.11 | E47: 0.11 | F47: 0.11 | G47: Sourced from latest annual report
...

Sheet Forecast
A2: Financial Statement Model for Wolters Kluwer
A3: € mm except per share
A5: Company name | B5: Wolters Kluwer N.V.
A6: Ticker | B6: WKL / WKL.AS
A7: Use average balances = 1, Use BOP balances = 0 | B7: 1
A8: Latest closing share price
A9: Latest closing share price date
A10: Latest fiscal year end date | B10: 2025-12-31
A11: Shares outstanding (millions) | B11: 231.8
A12: Select an operating scenario | B12: Base case
A14: INCOME STATEMENT | K14: 5 Year | M14: Comments
B15: 2024A | C15: 2025A | D15: 2026E | E15: 2027E | F15: 2028E | G15: 2029E | H15: 2030E | I15: 2031E | K15: CAGR
A17: Revenue | B17: ='Historical Data'!E16 -> 5916 | C17: ='Historical Data'!F16 -> 6125 | D17: =C17*(1+D38) -> 6431.25 | E17: =D17*(1+E38) -> 6813.9094 | F17: =E17*(1+F38) -> 7203.665 | G17: =F17*(1+G38) -> 7591.2222 | H17: =G17*(1+H38) -> 7969.265 | I17: =H17*(1+I38) -> 8333.4604 | K17: =(I17/C17)^(1/5)-1 -> 0.063515581 | M17: Prior-year revenue × forecast growth assumption.
A18: Cost of revenue (enter as -) | B18: ='Historical Data'!E17 -> -1626 | C18: ='Historical Data'!F17 -> -1625 | D18: =-D17*(1-D39) -> -1672.125 | E18: =-E17*(1-E39) -> -1757.9886 | F18: =-F17*(1-F39) -> -1851.3419 | G18: =-G17*(1-G39) -> -1943.3529 | H18: =-H17*(1-H39) -> -2032.1626 | I18: =-I17*(1-I39) -> -2116.699 | M18: Derived from forecast gross margin.
A19: Gross Profit | B19: ='Historical Data'!E18 -> 4290 | C19: ='Historical Data'!F18 -> 4500 | D19: =SUM(D17:D18) -> 4759.125 | E19: =SUM(E17:E18) -> 5055.9208 | F19: =SUM(F17:F18) -> 5352.3231 | G19: =SUM(G17:G18) -> 5647.8693 | H19: =SUM(H17:H18) -> 5937.1024 | I19: =SUM(I17:I18) -> 6216.7615 | M19: Revenue less cost of revenue
A20: Product development / R&D & editorial (enter as -) | B20: ='Historical Data'!E19 -> -688 | C20: ='Historical Data'!F19 -> -724 | D20: =-D17*D40 -> -771.75 | E20: =-E17*E40 -> -824.48303 | F20: =-F17*F40 -> -878.84713 | G20: =-G17*G40 -> -926.1291 | H20: =-H17*H40 -> -972.25033 | I20: =-I17*I40 -> -1016.6822 | M20: Revenue × forecast R&D expense %.
A21: Sales & Marketing (enter as -) | B21: ='Historical Data'!E20 -> -969 | C21: ='Historical Data'!F20 -> -975 | D21: =-D17*D41 -> -1016.1375 | E21: =-E17*E41 -> -1069.7838 | F21: =-F17*F41 -> -1123.7717 | G21: =-G17*G41 -> -1176.6394 | H21: =-H17*H41 -> -1227.2668 | I21: =-I17*I41 -> -1275.0194 | M21: Revenue × forecast S&M %.
A22: General & Administrative (enter as -) | B22: ='Historical Data'!E21 -> -1033 | C22: ='Historical Data'!F21 -> -1114 | D22: =-D17*0.182 -> -1170.4875 | E22: =-E17*0.18 -> -1226.5037 | F22: =-F17*0.177 -> -1275.0487 | G22: =-G17*0.175 -> -1328.4639 | H22: =-H17*0.174 -> -1386.6521 | I22: =-I17*0.174 -> -1450.0221 | M22: Revenue × forecast G&A %
A23: Amortization of acquired intangibles (enter as -) | B23: ='Historical Data'!E22 -> -149 | C23: ='Historical Data'!F22 -> -157 | D23: =-D17*0.025 -> -160.78125 | E23: =-E17*0.024 -> -163.53382 | F23: =-F17*0.023 -> -165.68429 | G23: =-G17*0.022 -> -167.00689 | H23: =-H17*0.021 -> -167.35457 | I23: =-I17*0.02 -> -166.66921 | M23: Forecast as declining % of revenue as existing acquisition intangibles amortize.
A24: Operating profit (EBIT) | B24: ='Historical Data'!E24 -> 1441 | C24: ='Historical Data'!F24 -> 1735 | D24: =SUM(D19:D23) -> 1639.9688 | E24: =SUM(E19:E23) -> 1771.6164 | F24: =SUM(F19:F23) -> 1908.9712 | G24: =SUM(G19:G23) -> 2049.63 | H24: =SUM(H19:H23) -> 2183.5786 | I24: =SUM(I19:I23) -> 2308.3685 | K24: =(I24/C24)^(1/5)-1 -> 0.058768797 | M24: Gross profit less operating expenses
A25: Interest income | B25: ='Historical Data'!E25 -> 52 | C25: ='Historical Data'!F25 -> 29 | D25: =D170 -> 27.96 | E25: =E170 -> 40.060284 | F25: =F170 -> 54.166749 | G25: =G170 -> 68.167026 | H25: =H170 -> 82.181737 | I25: =I170 -> 95.709334 | M25: Based on beginning cash and assumed cash yield.
A26: Interest expense (enter as -) | B26: ='Historical Data'!E26 -> -114 | C26: ='Historical Data'!F26 -> -115 | D26: =D166+D168 -> -142.62 | E26: =E166+E168 -> -142.62 | F26: =F166+F168 -> -142.62 | G26: =G166+G168 -> -147.374 | H26: =H166+H168 -> -147.374 | I26: =I166+I168 -> -147.374 | M26: Based on debt balances and assumed borrowing rate.
A27: Other expense, net (enter as -) | B27: ='Historical Data'!E27 -> -3 | C27: ='Historical Data'!F27 -> -2 | D27: -2 | E27: -2 | F27: -2 | G27: -2 | H27: -2 | I27: -2
A28: Pretax profit | B28: ='Historical Data'!E28 -> 1376 | C28: ='Historical Data'!F28 -> 1647 | D28: =SUM(D24:D27) -> 1523.3088 | E28: =SUM(E24:E27) -> 1667.0567 | F28: =SUM(F24:F27) -> 1818.518 | G28: =SUM(G24:G27) -> 1968.423 | H28: =SUM(H24:H27) -> 2116.3864 | I28: =SUM(I24:I27) -> 2254.7039 | M28: EBIT + net financing result.
A29: Taxes (enter expense as -) | B29: ='Historical Data'!E29 -> -299 | C29: ='Historical Data'!F29 -> -341 | D29: =-D28*D44 -> -319.89484 | E29: =-E28*E44 -> -350.08191 | F29: =-F28*F44 -> -381.88877 | G29: =-G28*G44 -> -413.36883 | H29: =-H28*H44 -> -444.44113 | I29: =-I28*I44 -> -473.48781 | M29: Pretax profit × forecast effective tax rate.
A30: Net income | B30: ='Historical Data'!E30 -> 1077 | C30: ='Historical Data'!F30 -> 1306 | D30: =SUM(D28:D29) -> 1203.4139 | E30: =SUM(E28:E29) -> 1316.9748 | F30: =SUM(F28:F29) -> 1436.6292 | G30: =SUM(G28:G29) -> 1555.0542 | H30: =SUM(H28:H29) -> 1671.9452 | I30: =SUM(I28:I29) -> 1781.2161 | K30: =(I30/C30)^(1/5)-1 -> 0.06403199 | M30: Pretax profit less taxes.
A32: Depreciation & amortization | B32: ='Historical Data'!E32 -> 479 | C32: ='Historical Data'!F32 -> 477 | D32: =D135 -> 334.425 | E32: =E135 -> 354.32329 | F32: =F135 -> 367.38691 | G32: =G135 -> 387.15233 | H32: =H135 -> 398.46325 | I32: =I135 -> 416.67302 | M32: Based on PP&E/intangible schedules and historical D&A intensity.
A33: EBITDA | B33: ='Historical Data'!E33 -> 1920 | C33: ='Historical Data'!F33 -> 2212 | D33: =D24+D32 -> 1974.3938 | E33: =E24+E32 -> 2125.9397 | F33: =F24+F32 -> 2276.3581 | G33: =G24+G32 -> 2436.7823 | H33: =H24+H32 -> 2582.0419 | I33: =I24+I32 -> 2725.0416 | K33: =(I33/C33)^(1/5)-1 -> 0.042599714
A34: Adjusted operating profit | B34: ='Historical Data'!E34 -> 1600 | C34: ='Historical Data'!F34 -> 1687 | D34: =D17*0.28 -> 1800.75 | E34: =E17*0.284 -> 1935.1503 | F34: =F17*0.288 -> 2074.6555 | G34: =G17*0.292 -> 2216.6369 | H34: =H17*0.295 -> 2350.9332 | I34: =I17*0.297 -> 2475.0378 | M34: Operating profit excluding acquired-intangible amortization / benchmark adjustments.
A35: Adjusted EBITDA | B35: ='Historical Data'!E35 -> 1930 | C35: ='Historical Data'!F35 -> 2007 | D35: =D34+D32 -> 2135.175 | E35: =E34+E32 -> 2289.4735 | F35: =F34+F32 -> 2442.0424 | G35: =G34+G32 -> 2603.7892 | H35: =H34+H32 -> 2749.3964 | I35: =I34+I32 -> 2891.7108 | M35: Adjusted operating profit + applicable D&A
A37: Growth rates & margins | K37: Step | M37: Comments
A38: Revenue growth | C38: =C17/B17-1 -> 0.035327924 | D38: 0.05 | E38: 0.0595 | F38: 0.0572 | G38: 0.0538 | H38: 0.0498 | I38: 0.0457 | M38: 2026E anchored to management’s expectation for “good organic growth”; later years gradually normalize toward mature mid-single-digit growth.
A39: Gross profit margin | B39: =B19/B17 -> 0.72515213 | C39: =C19/C17 -> 0.73469388 | D39: 0.74 | E39: 0.742 | F39: 0.743 | G39: 0.744 | H39: 0.745 | I39: 0.746 | M39: Assumes gradual improvement from higher recurring/cloud mix and operating leverage; model assumption based on historical margin trend.
A40: Product development / R&D % of revenue | B40: =-B20/B17 -> 0.11629479 | C40: =-C20/C17 -> 0.11820408 | D40: 0.12 | E40: 0.121 | F40: 0.122 | G40: 0.122 | H40: 0.122 | I40: 0.122 | M40: Increased to reflect heavier AI/product investment; 2026 guided product-development spending is 12–13% of revenue
A41: S&M % of revenue | B41: =-B21/B17 -> 0.1637931 | C41: =-C21/C17 -> 0.15918367 | D41: 0.158 | E41: 0.157 | F41: 0.156 | G41: 0.155 | H41: 0.154 | I41: 0.153 | M41: Gradual decline assumes scale efficiencies as recurring/cloud revenue grows; model assumption based on historical trend.
A42: G&A % of revenue | B42: =-SUM(B22:B23)/B17 -> 0.19979716 | C42: =-SUM(C22:C23)/C17 -> 0.2075102 | D42: =-SUM(D22:D23)/D17 -> 0.207 | E42: =-SUM(E22:E23)/E17 -> 0.204 | F42: =-SUM(F22:F23)/F17 -> 0.2 | G42: =-SUM(G22:G23)/G17 -> 0.197 | H42: =-SUM(H22:H23)/H17 -> 0.195 | I42: =-SUM(I22:I23)/I17 -> 0.194 | M42: Gradual decline assumes operating leverage and productivity gains as revenue scales; model assumption.
A43: Operating margin | B43: =B24/B17 -> 0.24357674 | C43: =C24/C17 -> 0.28326531 | D43: =D24/D17 -> 0.255 | E43: =E24/E17 -> 0.26 | F43: =F24/F17 -> 0.265 | G43: =G24/G17 -> 0.27 | H43: =H24/H17 -> 0.274 | I43: =I24/I17 -> 0.277 | M43: Formula-driven from gross margin and operating expenses; improves as revenue growth and operating leverage outweigh higher product investment.
A44: Effective tax rate | B44: =-B29/B28 -> 0.21729651 | C44: =-C29/C28 -> 0.20704311 | D44: 0.21 | E44: 0.21 | F44: 0.21 | G44: 0.21 | H44: 0.21 | I44: 0.21 | M44: Normalized model assumption; note that Wolters Kluwer’s 2026 benchmark tax-rate guidance is 23.5–24.5%, so 21% is more appropriate for IFRS effective tax only if separately justified
A45: Adjusted operating margin | B45: =B34/B17 -> 0.27045301 | C45: =C34/C17 -> 0.27542857 | D45: =D34/D17 -> 0.28 | E45: =E34/E17 -> 0.284 | F45: =F34/F17 -> 0.288 | G45: =G34/G17 -> 0.292 | H45: =H34/H17 -> 0.295 | I45: =I34/I17 -> 0.297 | M45: 2026E anchored directly to management guidance of ~28.0%; later years assume modest continued operating leverage.
A46: Total product development % of revenue | B46: ='Historical Data'!E47 -> 0.11 | C46: ='Historical Data'!F47 -> 0.11 | D46: 0.125 | E46: 0.125 | F46: 0.125 | G46: 0.125 | H46: 0.125 | I46: 0.125 | M46: 2026E–2031E held at 12.5%, the midpoint of management’s 2026 guidance range of 12–13%, explicitly linked to advancing the AI strategy.
...

Sheet Revenue Build_Empty
A2: CCH Axcess Expert AI - Price / Volume Build
A3: Fiscal year | B3: 2024 | C3: 2025 | D3: 2026 | E3: 2027 | F3: 2028 | G3: 2029 | H3: 2030 | I3: 2031
A4: Fiscal year end date | B4: 2024A | C4: 2025A | D4: 2026E | E4: 2027E | F4: 2028E | G4: 2029E | H4: 2030E | I4: 2031E
A5: Revenue & AI value build
A6: Core T&A revenue (without incremental AI scaling) | B6: 1561 | C6: 1660 | D6: =C6*(1+D25) -> 1776.2 | E6: =D6*(1+E25) -> 1900.534 | F6: =E6*(1+F25) -> 2024.0687 | G6: =F6*(1+G25) -> 2145.5128 | H6: =G6*(1+H25) -> 2263.516 | I6: =H6*(1+I25) -> 2376.6918
A7: Direct AI module revenue | B7: 0 | C7: 0 | D7: =D17*D18/1000000 -> 6.25 | E7: =E17*E18/1000000 -> 15.3 | F7: =F17*F18/1000000 -> 27.539625 | G7: =G17*G18/1000000 -> 43.191891 | H7: =H17*H18/1000000 -> 62.531303 | I7: =I17*I18/1000000 -> 85.848184
A8: Commercial expansion value | B8: 0 | C8: 0 | D8: =D7*D19 -> 0.9375 | E8: =E7*E19 -> 2.295 | F8: =F7*F19 -> 4.1309438 | G8: =G7*G19 -> 6.4787837 | H8: =H7*H19 -> 9.3796954 | I8: =I7*I19 -> 12.877228
A9: Total AI economic benefit | B9: 0 | C9: 0 | D9: =SUM(D7:D8) -> 7.1875 | E9: =SUM(E7:E8) -> 17.595 | F9: =SUM(F7:F8) -> 31.670569 | G9: =SUM(G7:G8) -> 49.670675 | H9: =SUM(H7:H8) -> 71.910998 | I9: =SUM(I7:I8) -> 98.725412
A10: T&A revenue incl. modeled AI benefit | B10: =B6+B9 -> 1561 | C10: =C6+C9 -> 1660 | D10: =D6+D9 -> 1783.3875 | E10: =E6+E9 -> 1918.129 | F10: =F6+F9 -> 2055.7393 | G10: =G6+G9 -> 2195.1835 | H10: =H6+H9 -> 2335.427 | I10: =I6+I9 -> 2475.4173
A11: % growth | C11: =C10/B10-1 -> 0.063420884 | D11: =D10/C10-1 -> 0.074329819 | E11: =E10/D10-1 -> 0.075553686 | F11: =F10/E10-1 -> 0.071741931 | G11: =G10/F10-1 -> 0.06783167 | H11: =H10/G10-1 -> 0.063886927 | I11: =I10/H10-1 -> 0.059942021
A13: Operating drivers
A14: CCH Axcess installed firms | D14: 10000 | E14: =D14*(1+E26) -> 10300 | F14: =E14*(1+F26) -> 10609 | G14: =F14*(1+G26) -> 10927.27 | H14: =G14*(1+H26) -> 11255.088 | I14: =H14*(1+I26) -> 11592.741
A15: AI adoption rate | B15: 0 | C15: 0 | D15: 0.04 | E15: 0.08 | F15: 0.13 | G15: 0.19 | H15: 0.26 | I15: 0.34
A16: Year-end agentic AI customers | B16: 0 | C16: 0 | D16: =D14*D15 -> 400 | E16: =E14*E15 -> 824 | F16: =F14*F15 -> 1379.17 | G16: =G14*G15 -> 2076.1813 | H16: =H14*H15 -> 2926.3229 | I16: =I14*I15 -> 3941.5319
A17: Average subscribed firms | B17: 0 | C17: 0 | D17: 250 | E17: =AVERAGE(D16,E16) -> 612 | F17: =AVERAGE(E16,F16) -> 1101.585 | G17: =AVERAGE(F16,G16) -> 1727.6757 | H17: =AVERAGE(G16,H16) -> 2501.2521 | I17: =AVERAGE(H16,I16) -> 3433.9274
A18: Incremental AI ARPU (€ / firm-year) | B18: 0 | C18: 0 | D18: 25000 | E18: 25000 | F18: 25000 | G18: 25000 | H18: 25000 | I18: 25000
A19: Commercial expansion value (% of direct revenue) | B19: 0 | C19: 0 | D19: 0.15 | E19: 0.15 | F19: 0.15 | G19: 0.15 | H19: 0.15 | I19: 0.15
A21: AI investment & cash flow build
A22: Product development intensity | B22: 0.11 | C22: 0.11 | D22: 0.125 | E22: 0.125 | F22: 0.125 | G22: 0.125 | H22: 0.125 | I22: 0.125
A23: T&A product development proxy | B23: =B6*B22 -> 171.71 | C23: =C6*C22 -> 182.6 | D23: =D6*D22 -> 222.025 | E23: =E6*E22 -> 237.56675 | F23: =F6*F22 -> 253.00859 | G23: =G6*G22 -> 268.1891 | H23: =H6*H22 -> 282.9395 | I23: =I6*I22 -> 297.08648
A24: AI share of T&A product development | B24: 0 | C24: 0.08 | D24: 0.08 | E24: 0.08 | F24: 0.08 | G24: 0.08 | H24: 0.08 | I24: 0.08
A25: T&A core revenue growth | C25: 0.07 | D25: 0.07 | E25: 0.07 | F25: 0.065 | G25: 0.06 | H25: 0.055 | I25: 0.05
A26: Installed-base growth | D26: 0.03 | E26: 0.03 | F26: 0.03 | G26: 0.03 | H26: 0.03 | I26: 0.03
A27: AI-attributed development investment | B27: =B23*B24 -> 0 | C27: =C23*C24 -> 14.608 | D27: =D23*D24 -> 17.762 | E27: =E23*E24 -> 19.00534 | F27: =F23*F24 -> 20.240687 | G27: =G23*G24 -> 21.455128 | H27: =H23*H24 -> 22.63516 | I27: =I23*I24 -> 23.766918
A28: AI delivery cost (% of direct AI revenue) | B28: 0.15 | C28: 0.15 | D28: 0.15 | E28: 0.15 | F28: 0.15 | G28: 0.15 | H28: 0.15 | I28: 0.15
A29: AI variable delivery cost | B29: =B7*B28 -> 0 | C29: =C7*C28 -> 0 | D29: =D7*D28 -> 0.9375 | E29: =E7*E28 -> 2.295 | F29: =F7*F28 -> 4.1309438 | G29: =G7*G28 -> 6.4787837 | H29: =H7*H28 -> 9.3796954 | I29: =I7*I28 -> 12.877228
A30: Recurring AI platform / governance fixed cost | B30: 0 | C30: 3 | D30: 5 | E30: =D30*1.03 -> 5.15 | F30: =E30*1.03 -> 5.3045 | G30: =F30*1.03 -> 5.463635 | H30: =G30*1.03 -> 5.6275441 | I30: =H30*1.03 -> 5.7963704
A31: Total AI cost | B31: =SUM(B27,B29,B30) -> 0 | C31: =SUM(C27,C29,C30) -> 17.608 | D31: =SUM(D27,D29,D30) -> 23.6995 | E31: =SUM(E27,E29,E30) -> 26.45034 | F31: =SUM(F27,F29,F30) -> 29.676131 | G31: =SUM(G27,G29,G30) -> 33.397547 | H31: =SUM(H27,H29,H30) -> 37.6424 | I31: =SUM(I27,I29,I30) -> 42.440516
A32: AI EBIT before tax | B32: =B9-B31 -> 0 | C32: =C9-C31 -> -17.608 | D32: =D9-D31 -> -16.512 | E32: =E9-E31 -> -8.85534 | F32: =F9-F31 -> 1.9944379 | G32: =G9-G31 -> 16.273128 | H32: =H9-H31 -> 34.268598 | I32: =I9-I31 -> 56.284896
A33: Cash tax on positive AI EBIT | B33: =IF(B32>0,B32*23.6%,0) -> 0 | C33: =IF(C32>0,C32*23.6%,0) -> 0 | D33: =IF(D32>0,D32*23.6%,0) -> 0 | E33: =IF(E32>0,E32*23.6%,0) -> 0 | F33: =IF(F32>0,F32*23.6%,0) -> 0.47068734 | G33: =IF(G32>0,G32*23.6%,0) -> 3.8404582 | H33: =IF(H32>0,H32*23.6%,0) -> 8.0873892 | I33: =IF(I32>0,I32*23.6%,0) -> 13.283235
A34: Incremental AI free cash flow | B34: =B32-B33 -> 0 | C34: =C32-C33 -> -17.608 | D34: =D32-D33 -> -16.512 | E34: =E32-E33 -> -8.85534 | F34: =F32-F33 -> 1.5237506 | G34: =G32-G33 -> 12.43267 | H34: =H32-H33 -> 26.181209 | I34: =I32-I33 -> 43.00166
A35: Cumulative AI ROI | C35: =(SUM($C$9:C9)-SUM($C$31:C31))/SUM($C$31:C31) -> -1 | D35: =(SUM($C$9:D9)-SUM($C$31:D31))/SUM($C$31:D31) -> -0.82600012 | E35: =(SUM($C$9:E9)-SUM($C$31:E31))/SUM($C$31:E31) -> -0.63424897 | F35: =(SUM($C$9:F9)-SUM($C$31:F31))/SUM($C$31:F31) -> -0.42060179 | G35: =(SUM($C$9:G9)-SUM($C$31:G31))/SUM($C$31:G31) -> -0.18885185 | H35: =(SUM($C$9:H9)-SUM($C$31:H31))/SUM($C$31:H31) -> 0.056749579 | I35: =(SUM($C$9:I9)-SUM($C$31:I31))/SUM($C$31:I31) -> 0.31219162

Sheet Integrated DCF
A2: Discounted Cash Flow Valuation - Wolters Kluwer
A3: € and shares in millions, except per share data
A4: Most recent fiscal year end | C4: 2025A | E4: Discount rate (WACC) | F4: =WACC!E21 -> 0.0798266
A5: First forecast year | C5: 2026E | E5: Long-term growth rate | F5: 0.025
A6: Valuation date | C6: 2026-08-25 | E6: Exit EBITDA multiple | F6: 12
A7: Primary method | C7: UFCF DCF | E7: AI incremental value | F7: =DCF!B49 -> 14.817892
A10: Unlevered Free Cash Flows
B11: 2025A | C11: 2026E | D11: 2027E | E11: 2028E | F11: 2029E | G11: 2030E | H11: 2031E
A13: Revenue | B13: =Forecast!C17 -> 6125 | C13: =Forecast!D17 -> 6431.25 | D13: =Forecast!E17 -> 6813.9094 | E13: =Forecast!F17 -> 7203.665 | F13: =Forecast!G17 -> 7591.2222 | G13: =Forecast!H17 -> 7969.265 | H13: =Forecast!I17 -> 8333.4604
A14: % growth | C14: =C13/B13-1 -> 0.05 | D14: =D13/C13-1 -> 0.0595 | E14: =E13/D13-1 -> 0.0572 | F14: =F13/E13-1 -> 0.0538 | G14: =G13/F13-1 -> 0.0498 | H14: =H13/G13-1 -> 0.0457
A15: EBITDA | B15: =Forecast!C35 -> 2007 | C15: =Forecast!D35 -> 2135.175 | D15: =Forecast!E35 -> 2289.4735 | E15: =Forecast!F35 -> 2442.0424 | F15: =Forecast!G35 -> 2603.7892 | G15: =Forecast!H35 -> 2749.3964 | H15: =Forecast!I35 -> 2891.7108
A16: % margin | B16: =B15/B13 -> 0.32767347 | C16: =C15/C13 -> 0.332 | D16: =D15/D13 -> 0.336 | E16: =E15/E13 -> 0.339 | F16: =F15/F13 -> 0.343 | G16: =G15/G13 -> 0.345 | H16: =H15/H13 -> 0.347
A17: EBIT | B17: =Forecast!C24 -> 1735 | C17: =Forecast!D24 -> 1639.9688 | D17: =Forecast!E24 -> 1771.6164 | E17: =Forecast!F24 -> 1908.9712 | F17: =Forecast!G24 -> 2049.63 | G17: =Forecast!H24 -> 2183.5786 | H17: =Forecast!I24 -> 2308.3685
A18: % margin | B18: =B17/B13 -> 0.28326531 | C18: =C17/C13 -> 0.255 | D18: =D17/D13 -> 0.26 | E18: =E17/E13 -> 0.265 | F18: =F17/F13 -> 0.27 | G18: =G17/G13 -> 0.274 | H18: =H17/H13 -> 0.277
A20: Tax on EBIT | B20: =-B17*21% -> -364.35 | C20: =-C17*21% -> -344.39344 | D20: =-D17*21% -> -372.03945 | E20: =-E17*21% -> -400.88396 | F20: =-F17*21% -> -430.4223 | G20: =-G17*21% -> -458.55151 | H20: =-H17*21% -> -484.75739
A21: Tax rate | B21: 0.21 | C21: 0.21 | D21: 0.21 | E21: 0.21 | F21: 0.21 | G21: 0.21 | H21: 0.21
A22: NOPAT (aka EBIAT) | B22: =B17+B20 -> 1370.65 | C22: =C17+C20 -> 1295.5753 | D22: =D17+D20 -> 1399.577 | E22: =E17+E20 -> 1508.0873 | F22: =F17+F20 -> 1619.2077 | G22: =G17+G20 -> 1725.0271 | H22: =H17+H20 -> 1823.6111
A25: Depreciation & amortization | B25: =Forecast!C32 -> 477 | C25: =Forecast!D32 -> 334.425 | D25: =Forecast!E32 -> 354.32329 | E25: =Forecast!F32 -> 367.38691 | F25: =Forecast!G32 -> 387.15233 | G25: =Forecast!H32 -> 398.46325 | H25: =Forecast!I32 -> 416.67302
A26: Changes in net working capital | B26: 0 | C26: =B31-C31 -> 103.96122 | D26: =C31-D31 -> 100.6589 | E26: =D31-E31 -> 102.29938 | F26: =E31-F31 -> 101.75364 | G26: =F31-G31 -> 99.291792 | H26: =G31-H31 -> 95.693937
A27: Capital expenditures | B27: =-'Historical Data'!F80 -> -305 | C27: =Forecast!D88 -> -353.71875 | D27: =Forecast!E88 -> -367.95111 | E27: =Forecast!F88 -> -381.79424 | F27: =Forecast!G88 -> -394.74355 | G27: =Forecast!H88 -> -406.43252 | H27: =Forecast!I88 -> -416.67302
A28: as % of revenue | B28: =-B27/B13 -> 0.049795918 | C28: =-C27/C13 -> 0.055 | D28: =-D27/D13 -> 0.054 | E28: =-E27/E13 -> 0.053 | F28: =-F27/F13 -> 0.052 | G28: =-G27/G13 -> 0.051 | H28: =-H27/H13 -> 0.05
A30: Unlevered free cash flows (UFCF) | B30: =SUM(B22,B25,B26,B27) -> 1542.65 | C30: =SUM(C22,C25,C26,C27) -> 1380.2428 | D30: =SUM(D22,D25,D26,D27) -> 1486.6081 | E30: =SUM(E22,E25,E26,E27) -> 1595.9793 | F30: =SUM(F22,F25,F26,F27) -> 1713.3701 | G30: =SUM(G22,G25,G26,G27) -> 1816.3496 | H30: =SUM(H22,H25,H26,H27) -> 1919.3051
A31: Net working capital | B31: ='Historical Data'!F54+'Historical Data'!F55+'Historical Data'!F56-'Historical Data'!F62-'Historical Data'!F63-'Historical Data'!F64 -> -1579 | C31: =Forecast!D52+Forecast!D53+Forecast!D54-Forecast!D60-Forecast!D61-Forecast!D62 -> -1682.9612 | D31: =Forecast!E52+Forecast!E53+Forecast!E54-Forecast!E60-Forecast!E61-Forecast!E62 -> -1783.6201 | E31: =Forecast!F52+Forecast!F53+Forecast!F54-Forecast!F60-Forecast!F61-Forecast!F62 -> -1885.9195 | F31: =Forecast!G52+Forecast!G53+Forecast!G54-Forecast!G60-Forecast!G61-Forecast!G62 -> -1987.6731 | G31: =Forecast!H52+Forecast!H53+Forecast!H54-Forecast!H60-Forecast!H61-Forecast!H62 -> -2086.9649 | H31: =Forecast!I52+Forecast!I53+Forecast!I54-Forecast!I60-Forecast!I61-Forecast!I62 -> -2182.6589
A32: as % of revenue | B32: =B31/B13 -> -0.25779592 | C32: =C31/C13 -> -0.26168493 | D32: =D31/D13 -> -0.26176164 | E32: =E31/E13 -> -0.2618 | F32: =F31/F13 -> -0.26183836 | G32: =G31/G13 -> -0.26187671 | H32: =H31/H13 -> -0.26191507
A35: Present value of UFCF
B36: 2025A | C36: 2026E | D36: 2027E | E36: 2028E | F36: 2029E | G36: 2030E | H36: 2031E
A37: Discount period | B37: 0 | C37: 1 | D37: 2 | E37: 3 | F37: 4 | G37: 5 | H37: 6
A38: Discount factor | B38: =1/(1+$F$4)^B37 -> 1 | C38: =1/(1+$F$4)^C37 -> 0.92607461 | D38: =1/(1+$F$4)^D37 -> 0.85761419 | E38: =1/(1+$F$4)^E37 -> 0.79421473 | F38: =1/(1+$F$4)^F37 -> 0.73550209 | G38: =1/(1+$F$4)^G37 -> 0.68112982 | H38: =1/(1+$F$4)^H37 -> 0.63077703
A39: UFCF | B39: =B30 -> 1542.65 | C39: =C30 -> 1380.2428 | D39: =D30 -> 1486.6081 | E39: =E30 -> 1595.9793 | F39: =F30 -> 1713.3701 | G39: =G30 -> 1816.3496 | H39: =H30 -> 1919.3051
A40: Present value of UFCF | B40: =B39*B38 -> 1542.65 | C40: =C39*C38 -> 1278.2078 | D40: =D39*D38 -> 1274.9362 | E40: =E39*E38 -> 1267.5503 | F40: =F39*F38 -> 1260.1873 | G40: =G39*G38 -> 1237.1699 | H40: =H39*H38 -> 1210.6536
A43: Terminal value - growth in perpetuity approach | E43: Terminal value - EBITDA multiple approach
A44: Long term growth rate | B44: =$F$5 -> 0.025 | E44: Terminal year EBITDA | H44: =H15 -> 2891.7108
A45: 2031 FCF x (1+g) | B45: =H30*(1+B44) -> 1967.2877 | E45: EBITDA multiple | H45: =$F$6 -> 12
A46: Terminal value in 2031 | B46: =B45/($F$4-B44) -> 35881.994 | E46: Terminal value in 2031 | H46: =H44*H45 -> 34700.529
A47: Present value of terminal value | B47: =B46*H38 -> 22633.537 | E47: Present value of terminal value | H47: =H46*H38 -> 21888.297
A48: Present value of stage 1 cash flows | B48: =SUM(C40:H40) -> 7528.705 | E48: Present value of stage 1 cash flows | H48: =B48 -> 7528.705
A49: Total enterprise value (TEV) | B49: =SUM(B47:B48) -> 30162.242 | E49: Enterprise value (stage 1 + 2) | H49: =SUM(H47:H48) -> 29417.002
A56: Net debt / AI value / shares
A57: Source doc | B57: 2025 Annual Report | E57: Source doc | F57: Date | G57: Shares
A58: Gross debt and equivalents | B58: ='Historical Data'!F87 -> 4971 | E58: Diluted share proxy | F58: 2026E | G58: =Shares!D12 -> 228
...

Sheet DCF
A2: CCH Axcess Expert AI - Incremental DCF / ROI
A3: € millions except per share data
A4: Most recent fiscal year end | C4: 2025A | E4: Discount rate (WACC) | F4: =WACC!E21 -> 0.0798266
A5: First forecast year | C5: 2026E | E5: Terminal growth rate | F5: 0.025
A6: Primary method | C6: Finite AI cash flows through 2031 | E6: AI investment hurdle reference | F6: 0.08
A7: Scenario | C7: Base case
A10: Incremental AI Cash Flows
B11: 2025A | C11: 2026E | D11: 2027E | E11: 2028E | F11: 2029E | G11: 2030E | H11: 2031E
A13: Total AI economic benefit | B13: ='Revenue Build_Empty'!C9 -> 0 | C13: ='Revenue Build_Empty'!D9 -> 7.1875 | D13: ='Revenue Build_Empty'!E9 -> 17.595 | E13: ='Revenue Build_Empty'!F9 -> 31.670569 | F13: ='Revenue Build_Empty'!G9 -> 49.670675 | G13: ='Revenue Build_Empty'!H9 -> 71.910998 | H13: ='Revenue Build_Empty'!I9 -> 98.725412
A14: Total AI cost | B14: ='Revenue Build_Empty'!C31 -> 17.608 | C14: ='Revenue Build_Empty'!D31 -> 23.6995 | D14: ='Revenue Build_Empty'!E31 -> 26.45034 | E14: ='Revenue Build_Empty'!F31 -> 29.676131 | F14: ='Revenue Build_Empty'!G31 -> 33.397547 | G14: ='Revenue Build_Empty'!H31 -> 37.6424 | H14: ='Revenue Build_Empty'!I31 -> 42.440516
A15: AI EBIT before tax | B15: ='Revenue Build_Empty'!C32 -> -17.608 | C15: ='Revenue Build_Empty'!D32 -> -16.512 | D15: ='Revenue Build_Empty'!E32 -> -8.85534 | E15: ='Revenue Build_Empty'!F32 -> 1.9944379 | F15: ='Revenue Build_Empty'!G32 -> 16.273128 | G15: ='Revenue Build_Empty'!H32 -> 34.268598 | H15: ='Revenue Build_Empty'!I32 -> 56.284896
A16: Cash tax on positive AI EBIT | B16: ='Revenue Build_Empty'!C33 -> 0 | C16: ='Revenue Build_Empty'!D33 -> 0 | D16: ='Revenue Build_Empty'!E33 -> 0 | E16: ='Revenue Build_Empty'!F33 -> 0.47068734 | F16: ='Revenue Build_Empty'!G33 -> 3.8404582 | G16: ='Revenue Build_Empty'!H33 -> 8.0873892 | H16: ='Revenue Build_Empty'!I33 -> 13.283235
A17: Incremental AI free cash flow | B17: ='Revenue Build_Empty'!C34 -> -17.608 | C17: ='Revenue Build_Empty'!D34 -> -16.512 | D17: ='Revenue Build_Empty'!E34 -> -8.85534 | E17: ='Revenue Build_Empty'!F34 -> 1.5237506 | F17: ='Revenue Build_Empty'!G34 -> 12.43267 | G17: ='Revenue Build_Empty'!H34 -> 26.181209 | H17: ='Revenue Build_Empty'!I34 -> 43.00166
A18: Cumulative AI benefit | B18: =SUM($B$13:B13) -> 0 | C18: =SUM($B$13:C13) -> 7.1875 | D18: =SUM($B$13:D13) -> 24.7825 | E18: =SUM($B$13:E13) -> 56.453069 | F18: =SUM($B$13:F13) -> 106.12374 | G18: =SUM($B$13:G13) -> 178.03474 | H18: =SUM($B$13:H13) -> 276.76015
A19: Cumulative AI cost | B19: =SUM($B$14:B14) -> 17.608 | C19: =SUM($B$14:C14) -> 41.3075 | D19: =SUM($B$14:D14) -> 67.75784 | E19: =SUM($B$14:E14) -> 97.433971 | F19: =SUM($B$14:F14) -> 130.83152 | G19: =SUM($B$14:G14) -> 168.47392 | H19: =SUM($B$14:H14) -> 210.91443
A20: Cumulative AI ROI | B20: =IF(B19=0,0,(B18-B19)/B19) -> -1 | C20: =IF(C19=0,0,(C18-C19)/C19) -> -0.82600012 | D20: =IF(D19=0,0,(D18-D19)/D19) -> -0.63424897 | E20: =IF(E19=0,0,(E18-E19)/E19) -> -0.42060179 | F20: =IF(F19=0,0,(F18-F19)/F19) -> -0.18885185 | G20: =IF(G19=0,0,(G18-G19)/G19) -> 0.056749579 | H20: =IF(H19=0,0,(H18-H19)/H19) -> 0.31219162
A21: Cumulative AI FCF | B21: =SUM($B$17:B17) -> -17.608 | C21: =SUM($B$17:C17) -> -34.12 | D21: =SUM($B$17:D17) -> -42.97534 | E21: =SUM($B$17:E17) -> -41.451589 | F21: =SUM($B$17:F17) -> -29.01892 | G21: =SUM($B$17:G17) -> -2.8377107 | H21: =SUM($B$17:H17) -> 40.16395
A23: Present Value of AI Free Cash Flows
B24: 2025A | C24: 2026E | D24: 2027E | E24: 2028E | F24: 2029E | G24: 2030E | H24: 2031E
A25: Discount period | B25: 0 | C25: 1 | D25: 2 | E25: 3 | F25: 4 | G25: 5 | H25: 6
A26: Discount factor | B26: =1/(1+$F$4)^B25 -> 1 | C26: =1/(1+$F$4)^C25 -> 0.92607461 | D26: =1/(1+$F$4)^D25 -> 0.85761419 | E26: =1/(1+$F$4)^E25 -> 0.79421473 | F26: =1/(1+$F$4)^F25 -> 0.73550209 | G26: =1/(1+$F$4)^G25 -> 0.68112982 | H26: =1/(1+$F$4)^H25 -> 0.63077703
A27: Incremental AI FCF | B27: =B17 -> -17.608 | C27: =C17 -> -16.512 | D27: =D17 -> -8.85534 | E27: =E17 -> 1.5237506 | F27: =F17 -> 12.43267 | G27: =G17 -> 26.181209 | H27: =H17 -> 43.00166
A28: Present value of AI FCF | B28: =B27*B26 -> -17.608 | C28: =C27*C26 -> -15.291344 | D28: =D27*D26 -> -7.5944652 | E28: =E27*E26 -> 1.2101851 | F28: =F27*F26 -> 9.1442546 | G28: =G27*G26 -> 17.832802 | H28: =H27*H26 -> 27.12446
A31: Primary valuation - finite cash flows
A32: NPV through 2031 (No TV) | B32: =SUM(B28:H28) -> 14.817892
A33: IRR | B33: =IF(AND(MIN(B17:H17)<0,MAX(B17:H17)>0),IRR(B17:H17),"N/M") -> 0.15687343
A34: Payback year | B34: =IF(C21>=0,2025+ABS(B21)/C17,IF(D21>=0,2026+ABS(C21)/D17,IF(E21>=0,2027+ABS(D21)/E17,IF(F21>=0,2028+ABS(E21)/F17,IF(G21>=0,2029+ABS(F21)/G17,IF(H21>=0,2030+ABS(G21)/H17,">2031")))))) -> 2030.066
A35: 2031 cumulative AI ROI | B35: =H20 -> 0.31219162
A36: Benefit / cost ratio | B36: =SUM(B13:H13)/SUM(B14:H14) -> 1.3121916
A39: Secondary valuation - terminal value
A40: Terminal growth rate | B40: =$F$5 -> 0.025
A41: Terminal value at 2031 | B41: =IF(H17<=0,0,H17*(1+B40)/($F$4-B40)) -> 803.92915
A42: PV of terminal value | B42: =B41*H26 -> 507.10004
A43: NPV incl. terminal value | B43: =B32+B42 -> 521.91793
A44: Terminal value % of total | B44: =IF(B43=0,0,B42/B43) -> 0.97160877
A48: Linked primary output
A49: AI NPV used in Integrated DCF | B49: =B32 -> 14.817892
A53: AI NPV Sensitivity - ARPU x Adoption
A54: Adoption multiplier | B54: 10000 | C54: 17500 | D54: 25000 | E54: 32500 | F54: 40000
